<?xml version="1.0" encoding="utf-8"?>

<robot name="hyq" xmlns:xacro="http://ros.org/wiki/xacro">

    <link name="base_link" />

    <joint name="floating_base" type="fixed">
        <origin xyz="0 0 0" rpy="0 0 0" />
        <parent link="base_link" />
        <child link="trunk" />
    </joint>

    <link name="trunk">
        <inertial>
            <origin xyz="0.056 0.0215 0.00358" />
            <mass value="60.96" />
            <inertia ixx="1.5725937" ixy="0.028375" ixz="-0.203139" iyy="8.5015928" iyz="-0.004462" izz="9.1954911" />
        </inertial>
        <visual>
            <geometry>
                <mesh filename="package://spotmicro_description/meshes/hyq/trunk/trunk.dae" scale="1 1 1" />
            </geometry>
        </visual>
        <collision>
            <geometry>
                <mesh filename="package://spotmicro_description/meshes/hyq/trunk/trunk.dae" scale="1 1 1" />
            </geometry>
        </collision>
    </link>

    <link name="l_front_hipassembly_link">
        <inertial>
            <origin xyz="0.04263 0.0 0.16931" />
            <mass value="2.93" />
            <inertia ixx="0.05071" ixy="-4e-05" ixz="-0.00159" iyy="0.05486" iyz="-5e-05" izz="0.00571" />
        </inertial>
        <visual>
            <origin rpy="0.0 0 0" xyz="0 0 0" />
            <geometry>
                <mesh filename="package://spotmicro_description/meshes/hyq/leg/hipassembly.dae" scale="1 1 1" />
            </geometry>
        </visual>
        <collision>
            <origin rpy="0.0 0 0" xyz="0 0 0" />
            <geometry>
                <mesh filename="package://spotmicro_description/meshes/hyq/leg/hipassembly.dae" scale="1 1 1" />
            </geometry>
        </collision>
    </link>

    <link name="l_front_upper_leg_link">
        <inertial>
            <origin xyz="0.15074 -0.02625 0.0" />
            <mass value="2.638" />
            <inertia ixx="0.00368" ixy="-0.00302" ixz="0.0001" iyy="0.02719" iyz="2e-05" izz="0.02811" />
        </inertial>
        <visual>
            <origin rpy="0.0 0 0" xyz="0 0 0" />
            <geometry>
                <mesh filename="package://spotmicro_description/meshes/hyq/leg/upperleg.dae" scale="1 1 1" />
            </geometry>
        </visual>
        <collision>
            <origin rpy="0.0 0 0" xyz="0 0 0" />
            <geometry>
                <mesh filename="package://spotmicro_description/meshes/hyq/leg/upperleg.dae" scale="1 1 1" />
            </geometry>
        </collision>
    </link>

    <link name="l_front_lower_leg_link">
        <inertial>
            <origin xyz="0.1254 4e-05 -0.0001" />
            <mass value="0.881" />
            <inertia ixx="0.00047" ixy="6e-05" ixz="-1e-05" iyy="0.01256" iyz="-0.0" izz="0.01233" />
        </inertial>
        <visual>
            <geometry>
                <mesh filename="package://spotmicro_description/meshes/hyq/leg/lowerleg.dae" scale="1 1 1" />
            </geometry>
            <material name="white" />
        </visual>
        <collision>
            <geometry>
                <mesh filename="package://spotmicro_description/meshes/hyq/leg/lowerleg.dae" scale="1 1 1" />
            </geometry>
        </collision>
    </link>

    <link name="l_front_toe_link">
        <inertial>
            <mass value="0.1" />
            <inertia ixx="0.03" iyy="0.03" izz="0.03" ixy="0.0" ixz="0.0" iyz="0.0" />
        </inertial>
        <collision>
            <origin rpy="0 0 0" xyz="0 0 0" />
            <geometry>
                <sphere radius="0.02175" />
            </geometry>
        </collision>
        <visual>
            <geometry>
                <sphere radius="0.02175" />
            </geometry>
            <material name="black" />
        </visual>
    </link>

    <joint name="l_front_hipassembly_joint" type="revolute">
        <origin rpy="0 1.57079632679 3.14159265359" xyz="0.3735 0.207 0" />
        <parent link="trunk" />
        <child link="l_front_hipassembly_link" />
        <axis xyz="0 0 1" />
        <limit effort="150" lower="-1.2217304764" upper="0.436332312999" velocity="12.0" />
        <dynamics damping="0.1" friction="0" />
        <safety_controller k_position="50" k_velocity="10" soft_lower_limit="-1.2217304764" soft_upper_limit="0.436332312999" />
    </joint>

    <joint name="l_front_upper_leg_joint" type="revolute">
        <origin rpy="1.57079632679 0 0" xyz="0.08 0 0" />
        <parent link="l_front_hipassembly_link" />
        <child link="l_front_upper_leg_link" />
        <axis xyz="0 0 1" />
        <limit effort="150" lower="-0.872664625997" upper="1.2217304764" velocity="12.0" />
        <dynamics damping="0.1" friction="0" />
        <safety_controller k_position="50" k_velocity="10" soft_lower_limit="-0.872664625997" soft_upper_limit="1.2217304764" />
    </joint>

    <joint name="l_front_lower_leg_joint" type="revolute">
        <origin rpy="0 0 0" xyz="0.35 0 0" />
        <parent link="l_front_upper_leg_link" />
        <child link="l_front_lower_leg_link" />
        <axis xyz="0 0 1" />
        <limit effort="150" lower="-2.44346095279" upper="-0.349065850399" velocity="12.0" />
        <dynamics damping="0.1" friction="0" />
        <safety_controller k_position="50" k_velocity="10" soft_lower_limit="-2.44346095279" soft_upper_limit="-0.349065850399" />
    </joint>

    <joint name="l_front_toe_joint" type="fixed">
        <origin rpy="1.57079632679 0 -1.57079632679" xyz="0.346 0 0" />
        <parent link="l_front_lower_leg_link" />
        <child link="l_front_toe_link" />
    </joint>

    <link name="r_front_hipassembly_link">
        <inertial>
            <origin xyz="0.04263 -0.0 -0.16931" />
            <mass value="2.93" />
            <inertia ixx="0.05071" ixy="4e-05" ixz="0.00159" iyy="0.05486" iyz="-5e-05" izz="0.00571" />
        </inertial>
        <visual>
            <origin rpy="3.14159265359 0 0" xyz="0 0 0" />
            <geometry>
                <mesh filename="package://spotmicro_description/meshes/hyq/leg/hipassembly.dae" scale="1 1 1" />
            </geometry>
        </visual>
        <collision>
            <origin rpy="3.14159265359 0 0" xyz="0 0 0" />
            <geometry>
                <mesh filename="package://spotmicro_description/meshes/hyq/leg/hipassembly.dae" scale="1 1 1" />
            </geometry>
        </collision>
    </link>

    <link name="r_front_upper_leg_link">
        <inertial>
            <origin xyz="0.15074 -0.02625 0.0" />
            <mass value="2.638" />
            <inertia ixx="0.00368" ixy="-0.00302" ixz="0.0001" iyy="0.02719" iyz="2e-05" izz="0.02811" />
        </inertial>
        <visual>
            <origin rpy="0.0 0 0" xyz="0 0 0" />
            <geometry>
                <mesh filename="package://spotmicro_description/meshes/hyq/leg/upperleg.dae" scale="1 1 1" />
            </geometry>
        </visual>
        <collision>
            <origin rpy="0.0 0 0" xyz="0 0 0" />
            <geometry>
                <mesh filename="package://spotmicro_description/meshes/hyq/leg/upperleg.dae" scale="1 1 1" />
            </geometry>
        </collision>
    </link>

    <link name="r_front_lower_leg_link">
        <inertial>
            <origin xyz="0.1254 4e-05 -0.0001" />
            <mass value="0.881" />
            <inertia ixx="0.00047" ixy="6e-05" ixz="-1e-05" iyy="0.01256" iyz="-0.0" izz="0.01233" />
        </inertial>
        <visual>
            <geometry>
                <mesh filename="package://spotmicro_description/meshes/hyq/leg/lowerleg.dae" scale="1 1 1" />
            </geometry>
            <material name="white" />
        </visual>
        <collision>
            <geometry>
                <mesh filename="package://spotmicro_description/meshes/hyq/leg/lowerleg.dae" scale="1 1 1" />
            </geometry>
        </collision>
    </link>

    <link name="r_front_toe_link">
        <inertial>
            <mass value="0.1" />
            <inertia ixx="0.03" iyy="0.03" izz="0.03" ixy="0.0" ixz="0.0" iyz="0.0" />
        </inertial>
        <collision>
            <origin rpy="0 0 0" xyz="0 0 0" />
            <geometry>
                <sphere radius="0.02175" />
            </geometry>
        </collision>
        <visual>
            <geometry>
                <sphere radius="0.02175" />
            </geometry>
            <material name="black" />
        </visual>
    </link>

    <joint name="r_front_hipassembly_joint" type="revolute">
        <origin rpy="0 1.57079632679 0" xyz="0.3735 -0.207 0" />
        <parent link="trunk" />
        <child link="r_front_hipassembly_link" />
        <axis xyz="0 0 1" />
        <limit effort="150" lower="-1.2217304764" upper="0.436332312999" velocity="12.0" />
        <dynamics damping="0.1" friction="0" />
        <safety_controller k_position="50" k_velocity="10" soft_lower_limit="-1.2217304764" soft_upper_limit="0.436332312999" />
    </joint>

    <joint name="r_front_upper_leg_joint" type="revolute">
        <origin rpy="-1.57079632679 0 0" xyz="0.08 0 0" />
        <parent link="r_front_hipassembly_link" />
        <child link="r_front_upper_leg_link" />
        <axis xyz="0 0 1" />
        <limit effort="150" lower="-0.872664625997" upper="1.2217304764" velocity="12.0" />
        <dynamics damping="0.1" friction="0" />
        <safety_controller k_position="50" k_velocity="10" soft_lower_limit="-0.872664625997" soft_upper_limit="1.2217304764" />
    </joint>

    <joint name="r_front_lower_leg_joint" type="revolute">
        <origin rpy="0 0 0" xyz="0.35 0 0" />
        <parent link="r_front_upper_leg_link" />
        <child link="r_front_lower_leg_link" />
        <axis xyz="0 0 1" />
        <limit effort="150" lower="-2.44346095279" upper="-0.349065850399" velocity="12.0" />
        <dynamics damping="0.1" friction="0" />
        <safety_controller k_position="50" k_velocity="10" soft_lower_limit="-2.44346095279" soft_upper_limit="-0.349065850399" />
    </joint>

    <joint name="r_front_toe_joint" type="fixed">
        <origin rpy="1.57079632679 0 -1.57079632679" xyz="0.346 0 0" />
        <parent link="r_front_lower_leg_link" />
        <child link="r_front_toe_link" />
    </joint>

    <link name="l_rear_hipassembly_link">
        <inertial>
            <origin xyz="0.04263 -0.0 -0.16931" />
            <mass value="2.93" />
            <inertia ixx="0.05071" ixy="4e-05" ixz="0.00159" iyy="0.05486" iyz="-5e-05" izz="0.00571" />
        </inertial>
        <visual>
            <origin rpy="3.14159265359 0 0" xyz="0 0 0" />
            <geometry>
                <mesh filename="package://spotmicro_description/meshes/hyq/leg/hipassembly.dae" scale="1 1 1" />
            </geometry>
        </visual>
        <collision>
            <origin rpy="3.14159265359 0 0" xyz="0 0 0" />
            <geometry>
                <mesh filename="package://spotmicro_description/meshes/hyq/leg/hipassembly.dae" scale="1 1 1" />
            </geometry>
        </collision>
    </link>

    <link name="l_rear_upper_leg_link">
        <inertial>
            <origin xyz="0.15074 0.02625 0.0" />
            <mass value="2.638" />
            <inertia ixx="0.00368" ixy="0.00302" ixz="-0.0001" iyy="0.02719" iyz="2e-05" izz="0.02811" />
        </inertial>
        <visual>
            <origin rpy="3.14159265359 0 0" xyz="0 0 0" />
            <geometry>
                <mesh filename="package://spotmicro_description/meshes/hyq/leg/upperleg.dae" scale="1 1 1" />
            </geometry>
        </visual>
        <collision>
            <origin rpy="3.14159265359 0 0" xyz="0 0 0" />
            <geometry>
                <mesh filename="package://spotmicro_description/meshes/hyq/leg/upperleg.dae" scale="1 1 1" />
            </geometry>
        </collision>
    </link>

    <link name="l_rear_lower_leg_link">
        <inertial>
            <origin xyz="0.1254 -4e-05 0.0001" />
            <mass value="0.881" />
            <inertia ixx="0.00047" ixy="-6e-05" ixz="1e-05" iyy="0.01256" iyz="-0.0" izz="0.01233" />
        </inertial>
        <visual>
            <geometry>
                <mesh filename="package://spotmicro_description/meshes/hyq/leg/lowerleg.dae" scale="1 1 1" />
            </geometry>
            <material name="white" />
        </visual>
        <collision>
            <geometry>
                <mesh filename="package://spotmicro_description/meshes/hyq/leg/lowerleg.dae" scale="1 1 1" />
            </geometry>
        </collision>
    </link>

    <link name="l_rear_toe_link">
        <inertial>
            <mass value="0.1" />
            <inertia ixx="0.03" iyy="0.03" izz="0.03" ixy="0.0" ixz="0.0" iyz="0.0" />
        </inertial>
        <collision>
            <origin rpy="0 0 0" xyz="0 0 0" />
            <geometry>
                <sphere radius="0.02175" />
            </geometry>
        </collision>
        <visual>
            <geometry>
                <sphere radius="0.02175" />
            </geometry>
            <material name="black" />
        </visual>
    </link>

    <joint name="l_rear_hipasembly_joint" type="revolute">
        <origin rpy="0 1.57079632679 3.14159265359" xyz="-0.3735 0.207 0" />
        <parent link="trunk" />
        <child link="l_rear_hipassembly_link" />
        <axis xyz="0 0 1" />
        <limit effort="150" lower="-1.2217304764" upper="0.436332312999" velocity="12.0" />
        <dynamics damping="0.1" friction="0" />
        <safety_controller k_position="50" k_velocity="10" soft_lower_limit="-1.2217304764" soft_upper_limit="0.436332312999" />
    </joint>

    <joint name="l_rear_upper_leg_joint" type="revolute">
        <origin rpy="1.57079632679 0 0" xyz="0.08 0 0" />
        <parent link="l_rear_hipassembly_link" />
        <child link="l_rear_upper_leg_link" />
        <axis xyz="0 0 1" />
        <limit effort="150" lower="-1.2217304764" upper="0.872664625997" velocity="12.0" />
        <dynamics damping="0.1" friction="0" />
        <safety_controller k_position="50" k_velocity="10" soft_lower_limit="-1.2217304764" soft_upper_limit="0.872664625997" />
    </joint>

    <joint name="l_rear_lower_leg_joint" type="revolute">
        <origin rpy="0 0 0" xyz="0.35 0 0" />
        <parent link="l_rear_upper_leg_link" />
        <child link="l_rear_lower_leg_link" />
        <axis xyz="0 0 1" />
        <limit effort="150" lower="0.349065850399" upper="2.44346095279" velocity="12.0" />
        <dynamics damping="0.1" friction="0" />
        <safety_controller k_position="50" k_velocity="10" soft_lower_limit="0.349065850399" soft_upper_limit="2.44346095279" />
    </joint>

    <joint name="l_rear_toe_joint" type="fixed">
        <origin rpy="1.57079632679 0 -1.57079632679" xyz="0.346 0 0" />
        <parent link="l_rear_lower_leg_link" />
        <child link="l_rear_toe_link" />
    </joint>

    <link name="r_rear_hipassembly_link">
        <inertial>
            <origin xyz="0.04263 0.0 0.16931" />
            <mass value="2.93" />
            <inertia ixx="0.05071" ixy="-4e-05" ixz="-0.00159" iyy="0.05486" iyz="-5e-05" izz="0.00571" />
        </inertial>
        <visual>
            <origin rpy="0.0 0 0" xyz="0 0 0" />
            <geometry>
                <mesh filename="package://spotmicro_description/meshes/hyq/leg/hipassembly.dae" scale="1 1 1" />
            </geometry>
        </visual>
        <collision>
            <origin rpy="0.0 0 0" xyz="0 0 0" />
            <geometry>
                <mesh filename="package://spotmicro_description/meshes/hyq/leg/hipassembly.dae" scale="1 1 1" />
            </geometry>
        </collision>
    </link>

    <link name="r_rear_upper_leg_link">
        <inertial>
            <origin xyz="0.15074 0.02625 0.0" />
            <mass value="2.638" />
            <inertia ixx="0.00368" ixy="0.00302" ixz="-0.0001" iyy="0.02719" iyz="2e-05" izz="0.02811" />
        </inertial>
        <visual>
            <origin rpy="3.14159265359 0 0" xyz="0 0 0" />
            <geometry>
                <mesh filename="package://spotmicro_description/meshes/hyq/leg/upperleg.dae" scale="1 1 1" />
            </geometry>
        </visual>
        <collision>
            <origin rpy="3.14159265359 0 0" xyz="0 0 0" />
            <geometry>
                <mesh filename="package://spotmicro_description/meshes/hyq/leg/upperleg.dae" scale="1 1 1" />
            </geometry>
        </collision>
    </link>

    <link name="r_rear_lower_leg_link">
        <inertial>
            <origin xyz="0.1254 -4e-05 0.0001" />
            <mass value="0.881" />
            <inertia ixx="0.00047" ixy="-6e-05" ixz="1e-05" iyy="0.01256" iyz="-0.0" izz="0.01233" />
        </inertial>
        <visual>
            <geometry>
                <mesh filename="package://spotmicro_description/meshes/hyq/leg/lowerleg.dae" scale="1 1 1" />
            </geometry>
            <material name="white" />
        </visual>
        <collision>
            <geometry>
                <mesh filename="package://spotmicro_description/meshes/hyq/leg/lowerleg.dae" scale="1 1 1" />
            </geometry>
        </collision>
    </link>

    <link name="r_rear_toe_link">
        <inertial>
            <mass value="0.1" />
            <inertia ixx="0.03" iyy="0.03" izz="0.03" ixy="0.0" ixz="0.0" iyz="0.0" />
        </inertial>
        <collision>
            <origin rpy="0 0 0" xyz="0 0 0" />
            <geometry>
                <sphere radius="0.02175" />
            </geometry>
        </collision>
        <visual>
            <geometry>
                <sphere radius="0.02175" />
            </geometry>
            <material name="black" />
        </visual>
    </link>

    <joint name="r_rear_hipassembly_joint" type="revolute">
        <origin rpy="0 1.57079632679 0" xyz="-0.3735 -0.207 0" />
        <parent link="trunk" />
        <child link="r_rear_hipassembly_link" />
        <axis xyz="0 0 1" />
        <limit effort="150" lower="-1.2217304764" upper="0.436332312999" velocity="12.0" />
        <dynamics damping="0.1" friction="0" />
        <safety_controller k_position="50" k_velocity="10" soft_lower_limit="-1.2217304764" soft_upper_limit="0.436332312999" />
    </joint>

    <joint name="r_rear_upper_leg_joint" type="revolute">
        <origin rpy="-1.57079632679 0 0" xyz="0.08 0 0" />
        <parent link="r_rear_hipassembly_link" />
        <child link="r_rear_upper_leg_link" />
        <axis xyz="0 0 1" />
        <limit effort="150" lower="-1.2217304764" upper="0.872664625997" velocity="12.0" />
        <dynamics damping="0.1" friction="0" />
        <safety_controller k_position="50" k_velocity="10" soft_lower_limit="-1.2217304764" soft_upper_limit="0.872664625997" />
    </joint>

    <joint name="r_rear_lower_leg_joint" type="revolute">
        <origin rpy="0 0 0" xyz="0.35 0 0" />
        <parent link="r_rear_upper_leg_link" />
        <child link="r_rear_lower_leg_link" />
        <axis xyz="0 0 1" />
        <limit effort="150" lower="0.349065850399" upper="2.44346095279" velocity="12.0" />
        <dynamics damping="0.1" friction="0" />
        <safety_controller k_position="50" k_velocity="10" soft_lower_limit="0.349065850399" soft_upper_limit="2.44346095279" />
    </joint>

    <joint name="r_rear_toe_joint" type="fixed">
        <origin rpy="1.57079632679 0 -1.57079632679" xyz="0.346 0 0" />
        <parent link="r_rear_lower_leg_link" />
        <child link="r_rear_toe_link" />
    </joint>

    <link name="hokuyo_frame">
        <inertial>
            <mass value="1e-5" />
            <origin xyz="0 0 0" rpy="0 0 0" />
            <inertia ixx="1e-6" iyy="1e-6" izz="1e-6" ixy="0.0" ixz="0.0" iyz="0.0" />
        </inertial>
        <collision>
            <origin rpy="0 0 0" xyz="0 0 0" />
            <geometry>
                <box size="0.1 0.1 0.1" />
            </geometry>
        </collision>
        <visual>
            <origin rpy="0 0 0" xyz="0 0 0" />
            <geometry>
                <mesh filename="package://spotmicro_description/meshes/hyq/hokuyo.dae" scale="1 1 1" />
            </geometry>
        </visual>
    </link>

    <joint name="hokuyo_joint" type="fixed">
        <axis xyz="0 1 0" />
        <origin rpy="0 0 0" xyz="0.3735 0 0.14" />
        <parent link="trunk" />
        <child link="hokuyo_frame" />
    </joint>

    <transmission name="trans_lf_haa_joint">
        <type>transmission_interface/SimpleTransmission</type>
        <joint name="lf_haa_joint">
            <hardwareInterface>hardware_interface/EffortJointInterface</hardwareInterface>
        </joint>
        <actuator name="lf_haa_joint_motor">
            <hardwareInterface>hardware_interface/EffortJointInterface</hardwareInterface>
            <mechanicalReduction>1</mechanicalReduction>
        </actuator>
    </transmission>

    <transmission name="trans_lf_hfe_joint">
        <type>transmission_interface/SimpleTransmission</type>
        <joint name="lf_hfe_joint">
            <hardwareInterface>hardware_interface/EffortJointInterface</hardwareInterface>
        </joint>
        <actuator name="lf_hfe_joint_motor">
            <hardwareInterface>hardware_interface/EffortJointInterface</hardwareInterface>
            <mechanicalReduction>1</mechanicalReduction>
        </actuator>
    </transmission>

    <transmission name="trans_lf_kfe_joint">
        <type>transmission_interface/SimpleTransmission</type>
        <joint name="lf_kfe_joint">
            <hardwareInterface>hardware_interface/EffortJointInterface</hardwareInterface>
        </joint>
        <actuator name="lf_kfe_joint_motor">
            <hardwareInterface>hardware_interface/EffortJointInterface</hardwareInterface>
            <mechanicalReduction>1</mechanicalReduction>
        </actuator>
    </transmission>

    <transmission name="trans_rf_haa_joint">
        <type>transmission_interface/SimpleTransmission</type>
        <joint name="rf_haa_joint">
            <hardwareInterface>hardware_interface/EffortJointInterface</hardwareInterface>
        </joint>
        <actuator name="rf_haa_joint_motor">
            <hardwareInterface>hardware_interface/EffortJointInterface</hardwareInterface>
            <mechanicalReduction>1</mechanicalReduction>
        </actuator>
    </transmission>

    <transmission name="trans_rf_hfe_joint">
        <type>transmission_interface/SimpleTransmission</type>
        <joint name="rf_hfe_joint">
            <hardwareInterface>hardware_interface/EffortJointInterface</hardwareInterface>
        </joint>
        <actuator name="rf_hfe_joint_motor">
            <hardwareInterface>hardware_interface/EffortJointInterface</hardwareInterface>
            <mechanicalReduction>1</mechanicalReduction>
        </actuator>
    </transmission>

    <transmission name="trans_rf_kfe_joint">
        <type>transmission_interface/SimpleTransmission</type>
        <joint name="rf_kfe_joint">
            <hardwareInterface>hardware_interface/EffortJointInterface</hardwareInterface>
        </joint>
        <actuator name="rf_kfe_joint_motor">
            <hardwareInterface>hardware_interface/EffortJointInterface</hardwareInterface>
            <mechanicalReduction>1</mechanicalReduction>
        </actuator>
    </transmission>

    <transmission name="trans_lh_haa_joint">
        <type>transmission_interface/SimpleTransmission</type>
        <joint name="lh_haa_joint">
            <hardwareInterface>hardware_interface/EffortJointInterface</hardwareInterface>
        </joint>
        <actuator name="lh_haa_joint_motor">
            <hardwareInterface>hardware_interface/EffortJointInterface</hardwareInterface>
            <mechanicalReduction>1</mechanicalReduction>
        </actuator>
    </transmission>

    <transmission name="trans_lh_hfe_joint">
        <type>transmission_interface/SimpleTransmission</type>
        <joint name="lh_hfe_joint">
            <hardwareInterface>hardware_interface/EffortJointInterface</hardwareInterface>
        </joint>
        <actuator name="lh_hfe_joint_motor">
            <hardwareInterface>hardware_interface/EffortJointInterface</hardwareInterface>
            <mechanicalReduction>1</mechanicalReduction>
        </actuator>
    </transmission>

    <transmission name="trans_lh_kfe_joint">
        <type>transmission_interface/SimpleTransmission</type>
        <joint name="lh_kfe_joint">
            <hardwareInterface>hardware_interface/EffortJointInterface</hardwareInterface>
        </joint>
        <actuator name="lh_kfe_joint_motor">
            <hardwareInterface>hardware_interface/EffortJointInterface</hardwareInterface>
            <mechanicalReduction>1</mechanicalReduction>
        </actuator>
    </transmission>

    <transmission name="trans_rh_haa_joint">
        <type>transmission_interface/SimpleTransmission</type>
        <joint name="rh_haa_joint">
            <hardwareInterface>hardware_interface/EffortJointInterface</hardwareInterface>
        </joint>
        <actuator name="rh_haa_joint_motor">
            <hardwareInterface>hardware_interface/EffortJointInterface</hardwareInterface>
            <mechanicalReduction>1</mechanicalReduction>
        </actuator>
    </transmission>

    <transmission name="trans_rh_hfe_joint">
        <type>transmission_interface/SimpleTransmission</type>
        <joint name="rh_hfe_joint">
            <hardwareInterface>hardware_interface/EffortJointInterface</hardwareInterface>
        </joint>
        <actuator name="rh_hfe_joint_motor">
            <hardwareInterface>hardware_interface/EffortJointInterface</hardwareInterface>
            <mechanicalReduction>1</mechanicalReduction>
        </actuator>
    </transmission>

    <transmission name="trans_rh_kfe_joint">
        <type>transmission_interface/SimpleTransmission</type>
        <joint name="rh_kfe_joint">
            <hardwareInterface>hardware_interface/EffortJointInterface</hardwareInterface>
        </joint>
        <actuator name="rh_kfe_joint_motor">
            <hardwareInterface>hardware_interface/EffortJointInterface</hardwareInterface>
            <mechanicalReduction>1</mechanicalReduction>
        </actuator>
    </transmission>

    <gazebo>
        <plugin name="gazebo_ros_control" filename="libgazebo_ros_control.so">
            <robotNamespace>/hyq</robotNamespace>
        </plugin>
    </gazebo>

    <gazebo>
        <plugin filename="libgazebo_ros_p3d.so" name="gazebo_ros_p3d">
            <robotNamespace>/hyq</robotNamespace>
            <bodyName>trunk</bodyName>
            <topicName>ground_truth</topicName>
            <frameName>world</frameName>
            <xyzOffsets>0 0 0</xyzOffsets>
            <rpyOffsets>0 0 0</rpyOffsets>
            <gaussianNoise>0</gaussianNoise>
            <alwaysOn>true</alwaysOn>
            <updateRate>250.0</updateRate>
        </plugin>
    </gazebo>

    <gazebo>
        <plugin filename="libgazebo_ros_imu.so" name="gazebo_ros_imu_controller">
            <robotNamespace>/hyq</robotNamespace>
            <topicName>imu/data</topicName>
            <serviceName>imu/service</serviceName>
            <bodyName>trunk</bodyName>
            <gaussianNoise>0</gaussianNoise>
            <rpyOffsets>0 0 0</rpyOffsets>
            <!--<updateRate>50.0</updateRate>-->
            <alwaysOn>true</alwaysOn>
            <gaussianNoise>0</gaussianNoise>
        </plugin>
    </gazebo>

    <gazebo reference="lf_foot">
        <kp>1000000.0</kp>
        <kd>100.0</kd>
        <mu1>1.0</mu1>
        <mu2>1.0</mu2>
        <maxVel>1.0</maxVel>
        <maxContacts>1</maxContacts>
        <sensor name="lf_foot_contact_sensor" type="contact">
            <always_on>true</always_on>
            <update_rate>250.0</update_rate>
            <contact>
                <collision>>hyq::lf_lowerleg::lf_lowerleg_fixed_joint_lump__lf_foot_collision_1</collision>
            </contact>
            <plugin filename="libgazebo_ros_bumper.so" name="lf_foot_bumper">
                <bumperTopicName>/hyq/lf_foot_bumper</bumperTopicName>
                <frameName>lf_foot</frameName>
                <robotNamespace>hyq</robotNamespace>
            </plugin>
        </sensor>
        <material>Gazebo/Black</material>
    </gazebo>

    <gazebo reference="rf_foot">
        <kp>1000000.0</kp>
        <kd>100.0</kd>
        <mu1>1.0</mu1>
        <mu2>1.0</mu2>
        <maxVel>1.0</maxVel>
        <maxContacts>1</maxContacts>
        <sensor name="rf_foot_contact_sensor" type="contact">
            <always_on>true</always_on>
            <update_rate>250.0</update_rate>
            <contact>
                <collision>>hyq::rf_lowerleg::rf_lowerleg_fixed_joint_lump__rf_foot_collision_1</collision>
            </contact>
            <plugin filename="libgazebo_ros_bumper.so" name="rf_foot_bumper">
                <bumperTopicName>/hyq/rf_foot_bumper</bumperTopicName>
                <frameName>rf_foot</frameName>
                <robotNamespace>hyq</robotNamespace>
            </plugin>
        </sensor>
        <material>Gazebo/Black</material>
    </gazebo>

    <gazebo reference="lh_foot">
        <kp>1000000.0</kp>
        <kd>100.0</kd>
        <mu1>1.0</mu1>
        <mu2>1.0</mu2>
        <maxVel>1.0</maxVel>
        <maxContacts>1</maxContacts>
        <sensor name="lh_foot_contact_sensor" type="contact">
            <always_on>true</always_on>
            <update_rate>250.0</update_rate>
            <contact>
                <collision>>hyq::lh_lowerleg::lh_lowerleg_fixed_joint_lump__lh_foot_collision_1</collision>
            </contact>
            <plugin filename="libgazebo_ros_bumper.so" name="lh_foot_bumper">
                <bumperTopicName>/hyq/lh_foot_bumper</bumperTopicName>
                <frameName>lh_foot</frameName>
                <robotNamespace>hyq</robotNamespace>
            </plugin>
        </sensor>
        <material>Gazebo/Black</material>
    </gazebo>

    <gazebo reference="rh_foot">
        <kp>1000000.0</kp>
        <kd>100.0</kd>
        <mu1>1.0</mu1>
        <mu2>1.0</mu2>
        <maxVel>1.0</maxVel>
        <maxContacts>1</maxContacts>
        <sensor name="rh_foot_contact_sensor" type="contact">
            <always_on>true</always_on>
            <update_rate>250.0</update_rate>
            <contact>
                <collision>hyq::rh_lowerleg::rh_lowerleg_fixed_joint_lump__rh_foot_collision_1</collision>
            </contact>
            <plugin filename="libgazebo_ros_bumper.so" name="rh_foot_bumper">
                <bumperTopicName>/hyq/rh_foot_bumper</bumperTopicName>
                <frameName>rh_foot</frameName>
                <robotNamespace>hyq</robotNamespace>
            </plugin>
        </sensor>
        <material>Gazebo/Black</material>
    </gazebo>
    <!--
    <gazebo reference="trunk">
        <kp>1000.0</kp>
        <kd>1000.0</kd>
        <mu1>0.5</mu1>
        <mu2>0.5</mu2>
        <material>Gazebo/Red</material>
    </gazebo>

    <gazebo reference="lf_hipassembly">
        <kp>1000.0</kp>
        <kd>1000.0</kd>
        <mu1>0.5</mu1>
        <mu2>0.5</mu2>
    </gazebo>

    <gazebo reference="lf_upperleg">
        <kp>1000.0</kp>
        <kd>1000.0</kd>
        <mu1>0.5</mu1>
        <mu2>0.5</mu2>
    </gazebo>

    <gazebo reference="lf_lowerleg">
        <kp>1000.0</kp>
        <kd>1000.0</kd>
        <mu1>0.5</mu1>
        <mu2>0.5</mu2>
    </gazebo>

    <gazebo reference="lf_foot">
        <kp>1000.0</kp>
        <kd>1000.0</kd>
        <mu1>100000000000000000.0</mu1>
        <mu2>100000000000000000.0</mu2>
        <material>Gazebo/Red</material>
    </gazebo>

    <gazebo reference="rf_hipassembly">
        <kp>1000.0</kp>
        <kd>1000.0</kd>
        <mu1>0.5</mu1>
        <mu2>0.5</mu2>
    </gazebo>

    <gazebo reference="rf_upperleg">
        <kp>1000.0</kp>
        <kd>1000.0</kd>
        <mu1>0.5</mu1>
        <mu2>0.5</mu2>
    </gazebo>

    <gazebo reference="rf_lowerleg">
        <kp>1000.0</kp>
        <kd>1000.0</kd>
        <mu1>0.5</mu1>
        <mu2>0.5</mu2>
    </gazebo>

    <gazebo reference="rf_foot">
        <kp>1000.0</kp>
        <kd>1000.0</kd>
        <mu1>100000000000000000.0</mu1>
        <mu2>100000000000000000.0</mu2>
        <material>Gazebo/Red</material>
    </gazebo>

    <gazebo reference="lh_hipassembly">
        <kp>1000.0</kp>
        <kd>1000.0</kd>
        <mu1>0.5</mu1>
        <mu2>0.5</mu2>
    </gazebo>

    <gazebo reference="lh_upperleg">
        <kp>1000.0</kp>
        <kd>1000.0</kd>
        <mu1>0.5</mu1>
        <mu2>0.5</mu2>
    </gazebo>

    <gazebo reference="lh_lowerleg">
        <kp>1000.0</kp>
        <kd>1000.0</kd>
        <mu1>0.5</mu1>
        <mu2>0.5</mu2>
    </gazebo>

    <gazebo reference="lh_foot">
        <kp>1000.0</kp>
        <kd>1000.0</kd>
        <mu1>100000000000000000.0</mu1>
        <mu2>100000000000000000.0</mu2>
        <material>Gazebo/Red</material>
    </gazebo>

    <gazebo reference="rh_hipassembly">
        <kp>1000.0</kp>
        <kd>1000.0</kd>
        <mu1>0.5</mu1>
        <mu2>0.5</mu2>
    </gazebo>

    <gazebo reference="rh_upperleg">
        <kp>1000.0</kp>
        <kd>1000.0</kd>
        <mu1>0.5</mu1>
        <mu2>0.5</mu2>
    </gazebo>

    <gazebo reference="rh_lowerleg">
        <kp>1000.0</kp>
        <kd>1000.0</kd>
        <mu1>0.5</mu1>
        <mu2>0.5</mu2>
    </gazebo>

    <gazebo reference="rh_foot">
        <kp>1000.0</kp>
        <kd>1000.0</kd>
        <mu1>100000000000000000.0</mu1>
        <mu2>100000000000000000.0</mu2>
        <material>Gazebo/Red</material>
    </gazebo>
-->
    <gazebo reference="hokuyo_link">
        <sensor type="gpu_ray" name="head_hokuyo_sensor">
            <pose>0 0 0 0 0 0</pose>
            <visualize>false</visualize>
            <update_rate>40</update_rate>
            <ray>
                <scan>
                    <horizontal>
                        <samples>720</samples>
                        <resolution>1</resolution>
                        <min_angle>-1.570796</min_angle>
                        <max_angle>1.570796</max_angle>
                    </horizontal>
                </scan>
                <range>
                    <min>0.10</min>
                    <max>30.0</max>
                    <resolution>0.01</resolution>
                </range>
                <noise>
                    <type>gaussian</type>
                    <!-- Noise parameters based on published spec for Hokuyo laser
                        achieving "+-30mm" accuracy at range < 10m.  A mean of 0.0m and
                        stddev of 0.01m will put 99.7% of samples within 0.03m of the true
                        reading. -->
                    <mean>0.0</mean>
                    <stddev>0.01</stddev>
                </noise>
            </ray>
            <plugin name="gazebo_ros_head_hokuyo_controller" filename="libgazebo_ros_gpu_laser.so">
                <topicName>/hyq/laser/scan</topicName>
                <frameName>hokuyo_link</frameName>
            </plugin>
        </sensor>
    </gazebo>
</robot>